Workbook

Sheet README — Assumptions & Sources
B2: MODEL AUDIT — READ ME, ASSUMPTIONS & SOURCES
B3: Adaptive Vertical Densification: Rooftop Co-Living Extension | Hyderabad | Audited Aug 2026
B5: 1. WHAT THIS AUDIT CHANGED
B6: • Levered cash flow to equity was ADDING the loan payment to NOI instead of subtracting it (=NOI+DebtService instead of NOI-DebtService). This single error inflated every levered return metric in the file — Levered Project IRR, Developer Equity IRR, MOIC, and 10-year Host Payout all flowed from it. Fixed in both Model 1 and Model 2.
B7: • The 10-year loan amortization schedule had two compounding sign errors that made the outstanding loan balance GROW every year instead of paying down (Rs.63.6mm growing to Rs.291mm by Year 10, instead of amortizing to a lower balance). Rebuilt with a consistent, correct sign convention — balance now pays down normally.
B8: • DSCR (debt service coverage ratio) was computed as NOI / a negative number, producing impossible negative DSCR values (e.g. -1.58x) even though NOI safely covered debt service. Fixed — DSCR now correctly reads ~1.2x-1.8x, rising as the loan amortizes.
B9: • The model calculated a Year-10 exit/terminal value but never actually fed it into any IRR, MOIC, or cash-flow calculation — all return metrics were hold-period-only with no assumed exit, while the Opportunity Cost tab silently assumed an exit was already included. Fixed: Year-10 cash flows now include net-of-debt sale proceeds (levered) / gross sale proceeds (unlevered), split through the same JV waterfall as operating cash flow.
B10: • The Opportunity Cost tab was double-counting terminal value once the above fix was applied (added again on top of the now-inclusive cumulative cash flow row). Fixed — that value is now a memo line only.
B11: • The Executive Dashboard's Model 2 'Host Wealth Created' cell used an ad hoc formula that also double-counted terminal value. Fixed to reference the (now correct) cumulative payout.
B12: • The 2-way rent/occupancy sensitivity grid scaled a single base-case IRR proportionally by revenue ratios — mathematically invalid, since OpEx and debt service are not proportional to revenue. Rebuilt as 25 fully reconstructed 10-year cash-flow chains, each run through IRR() independently (see sheet 5, section 5.3).
B13: • Total Beds in the Space Program used a fragile IF() that matched on the literal typology name text — silently wrong if anyone edited a label. Replaced with an explicit, auditable 'Beds / Unit' input column.
B14: • Bed rents and the external TDR market rate were checked against public Hyderabad listings (Aug 2026). Two were revised — see section 3 below — because they weren't supportable against comparable market data.
B16: 2. HOW TO READ THE MODEL
B17: Yellow fill | C17: Hardcoded input — change these to stress-test the model.
B18: Light-grey fill, bold text | C18: Formula / calculated cell — do not hardcode over these.
B19: Amber fill (this sheet only) | C19: High-risk / unverified assumption — confirm before underwriting.
B20: Green fill (this sheet only) | C20: Assumption checked against public market data, Aug 2026.
B22: Sheet flow: 1) Space Program sets areas/unit mix/beds → 2) CPM & CapEx builds the construction budget from those areas → 3) & 4) Model 1 / Model 2 each take the CapEx total and run a full capital stack, 10-yr cash flow, JV waterfall, amortization schedule and return metrics → 5) Opportunity Cost compares the host's options and stress-tests rent/occupancy → 0) Dashboard summarizes both models side by side with sanity checks.
B24: 3. KEY MARKET ASSUMPTIONS — WHAT WE CHECKED, AND AGAINST WHAT
B25: Assumption | C25: Value Used | D25: Basis / Source (checked Aug 2026) | E25: Status
B26: Type A rent (single micro-studio) | C26: Rs.22,000/bed/mo | D26: Revised down from Rs.26,000. Premium single-occupancy co-living in Hyderabad (HITEC City / Financial District) tops out ~Rs.20,000-22,000 (Housr, Zolo listings; Hans India/Colliers, May 2025). | E26: REVISED
B27: Type B rent (twin sharing) | C27: Rs.15,500/bed/mo | D27: Revised down from Rs.16,500. Premium twin-sharing benchmarks ~Rs.13,000-16,500 (LBB, SquareYards listings, checked Aug 2026). Sits at the upper end — re-validate against 2-3 live comparables before underwriting. | E27: REVISED
B28: Type C rent (quad suite) | C28: Rs.13,000/bed/mo | D28: Revised down from Rs.15,000. Comparable triple/quad-sharing runs ~Rs.11,000-15,000 (LBB, checked Aug 2026). | E28: REVISED
B29: External TDR market rate | C29: Rs.150/sq.ft BUA | D29: Revised down from Rs.1,200 — HIGH RISK, RE-VERIFY. Only public benchmark found (myopenplots.com, Mar 2026) puts TDR price impact in comparable West Hyderabad micro-markets at Rs.90-140/sq.ft, an order of magnitude below the original figure, which could not be traced to any GHMC TDR-cell rate or registered DRC transaction. Confirm via tdr.ghmc.telangana.gov.in before relying on Model 2. | E29: HIGH RISK — VERIFY
B30: LGSF structural framing cost | C30: Rs.640/sq.ft | D30: Validated. India supplier quotes (IndiaMART, 2025-26) cluster Rs.650-2,000/sq.ft depending on span/finish; Rs.640 sits at the efficient/high-volume end — plausible for a repetitive factory-built module but confirm with a firm EPC quote. | E30: VALIDATED (RANGE)
B31: Senior debt interest rate | C31: 9.75% p.a. | D31: Validated. Indian commercial/CRE property loan rates in 2026 span ~8.5%-15% (HDFC 9.25-10.25%, SBI ~10%+, Bajaj Finance from 8%). 9.75% sits centrally — reasonable planning rate, but not a quoted term sheet. | E31: VALIDATED (RANGE)
B32: Senior debt LTV | C32: 65% | D32: Standard institutional CRE construction-facility leverage in India (typically 60-70% LTC for income-producing assets with a credible sponsor). | E32: REASONABLE
B33: Exit / terminal capitalization rate | C33: 8.50% | D33: Broadly consistent with cap rates quoted for stabilized, professionally managed rental residential / co-living assets in India (commonly cited 7.5%-9.5% range). Not project-specific — commission a third-party appraisal before exit. | E33: REASONABLE
B34: Operating expense ratio | C34: 28% of EGR | D34: On the efficient/optimistic end for a full-service, furniture+F&B-adjacent co-living operation; comparable managed operators often run 30-40% of revenue. Kept as an editable input — flagged for validation against operator P&Ls (Zolo/Stanza Living/Colive) before underwriting. | E34: FLAGGED — VALIDATE
B35: Rental escalation | C35: 5.0% every 2 years (~2.47%/yr effective) | D35: Conservative relative to common Indian lease escalation conventions (often 5% annually, or 15% every 3 years). Kept as-is; increasing it would improve returns further, so this is a conservative bias in the model, not a red flag. | E35: CONSERVATIVE
B36: Rooftop maintenance drag, 'Do Nothing' scenario | C36: Rs.18.5 lakh over 10 yrs | D36: Planning-level placeholder for a host doing nothing with the roof (waterproofing, structural upkeep). Not sourced to a specific vendor quote — treat as illustrative. | E36: PLANNING ESTIMATE
B38: 4. WHAT REMAINS ILLUSTRATIVE / OUT OF SCOPE FOR THIS AUDIT
B39: • The site ('Vantage Line Complex', Bandlaguda/TSPA Corridor) and building parameters (roof area, floor count) are the user's own project inputs and were not independently verified — they are treated as given planning assumptions, not researched facts.
B40: • Regulatory references (TG-bPASS / TS-bPASS, TDR mechanics) are real Telangana systems (confirmed via tgbpass.telangana.gov.in and the GHMC TDR portal) — but this workbook does not confirm that THIS SPECIFIC project would qualify for or receive TDR/FAR loading; that requires a structural/statutory feasibility opinion from a licensed architect and structural engineer, which is outside the scope of a financial model.
B41: • Construction line-item rates (anchoring, cladding, MEP, fitout, soft costs) beyond the LGSF framing line were not individually re-priced against fresh quotes — treat the CapEx build-up as a credible planning-stage budget, not a tendered EPC price.
B42: • This is a financial planning model, not investment, legal, tax or engineering advice.

Sheet 0. Executive Dashboard
B2: EXECUTIVE REAL ESTATE & CPM DASHBOARD
B3: Adaptive Vertical Densification: Rooftop Co-Living Extension | Hyderabad 2026
B5: EXECUTIVE KPI & INVESTMENT BENCHMARK COMPARISON
B6: Core Investment Metric / KPI | C6: Model 1 (In-House TDR) | D6: Model 2 (External TDR) | E6: Variance / Delta
B7: Total Project CapEx (Turnkey) | C7: ='3. Model 1 (In-House TDR)'!C9 | D7: ='4. Model 2 (External TDR)'!C10 | E7: =D7-C7
B8: External TDR Landed Cost | C8: ='3. Model 1 (In-House TDR)'!C7 | D8: ='4. Model 2 (External TDR)'!C8 | E8: =D8-C8
B9: Senior Bank Debt Required (65% LTV) | C9: ='3. Model 1 (In-House TDR)'!C12 | D9: ='4. Model 2 (External TDR)'!C13 | E9: =D9-C9
B10: Developer (GP) Equity Outflow (35%) | C10: ='3. Model 1 (In-House TDR)'!C13 | D10: ='4. Model 2 (External TDR)'!C14 | E10: =D10-C10
B11: Developer (GP) Equity IRR | C11: ='3. Model 1 (In-House TDR)'!C40 | D11: ='4. Model 2 (External TDR)'!C41 | E11: =D11-C11
B12: Levered Project IRR | C12: ='3. Model 1 (In-House TDR)'!C39 | D12: ='4. Model 2 (External TDR)'!C40 | E12: =D12-C12
B13: Unlevered Project IRR | C13: ='3. Model 1 (In-House TDR)'!C38 | D13: ='4. Model 2 (External TDR)'!C39 | E13: =D13-C13
B14: Developer Equity Multiple (MOIC) | C14: ='3. Model 1 (In-House TDR)'!C41 | D14: ='4. Model 2 (External TDR)'!C42 | E14: =D14-C14
B15: Stabilized DSCR (Year 2) | C15: ='3. Model 1 (In-House TDR)'!C44 | D15: ='4. Model 2 (External TDR)'!C45 | E15: =D15-C15
B16: 10-Year Cumulative Host Payout | C16: ='3. Model 1 (In-House TDR)'!C42 | D16: ='4. Model 2 (External TDR)'!C43 | E16: =D16-C16
B17: Host 10-Year Net Wealth Created | C17: ='5. Opportunity Cost'!E13 | D17: ='4. Model 2 (External TDR)'!C43 | E17: =D17-C17
B19: MODEL DIAGNOSTICS & SANITY CHECKS (auto-flag if inputs are changed)
B20: Check | C20: Model 1 | D20: Model 2 | E20: Pass / Fail Rule
B21: Year-1 DSCR (tightest year) | C21: ='3. Model 1 (In-House TDR)'!L39 | D21: ='4. Model 2 (External TDR)'!L40 | E21: >= 1.25x bank covenant
B22: Leverage effect (Levered IRR vs Unlevered IRR) | C22: =IF(C12>C13,"Accretive (+)","Dilutive (-)") | D22: =IF(D12>D13,"Accretive (+)","Dilutive (-)") | E22: Accretive expected: NOI yield > cost of debt
B23: Cost of debt vs Unlevered Project IRR | C23: =IF('3. Model 1 (In-House TDR)'!C14<C13,"OK: debt cheaper than asset yield","WARNING: debt costlier than asset yield") | D23: =IF('4. Model 2 (External TDR)'!C15<D13,"OK: debt cheaper than asset yield","WARNING: debt costlier than asset yield") | E23: Debt rate should sit below unlevered IRR
B24: Debt Yield on Cost (Stabilised NOI / Loan Amount) | C24: ='3. Model 1 (In-House TDR)'!E25/'3. Model 1 (In-House TDR)'!C12 | D24: ='4. Model 2 (External TDR)'!E26/'4. Model 2 (External TDR)'!C13 | E24: Lenders typically want >= 9-10%
B25: Loan-to-Cost sanity (Senior Debt / Total CapEx) | C25: ='3. Model 1 (In-House TDR)'!C12/'3. Model 1 (In-House TDR)'!C9 | D25: ='4. Model 2 (External TDR)'!C13/'4. Model 2 (External TDR)'!C10 | E25: Should equal input LTV (65%)

Sheet 1. Space Program
B2: SPACE PROGRAMMING & ZONING SCHEDULE
B3: Option 1 Site: Vantage Line Complex, Bandlaguda / TSPA Corridor, Hyderabad (Host Roof: 3,500 m²)
B5: 1.1 HOST BUILDING ROOFTOP PARAMETERS
B6: Parameter | C6: Value | D6: Unit
B7: Host Building Roof Plate Area (3,500 m²) | C7: 37673 | D7: sq.ft
B8: Less: 3 Staircase / Lift Mumty Cores & MEP Shafts | C8: 1673 | D8: sq.ft
B9: Net Usable Roof Footprint Available | C9: =C7-C8 | D9: sq.ft
B10: Vertical Extension Floors Proposed | C10: 2 | D10: Floors
B11: Total Rooftop Enclosed BUA (TDR Loaded) | C11: 30000 | D11: sq.ft
B12: Total Open-to-Sky Terrace & Bioclimatic Deck | C12: 24000 | D12: sq.ft
B13: Total Development Program Area | C13: =C11+C12 | D13: sq.ft
B15: 1.2 CO-LIVING POD UNIT MIX & REVENUE SCHEDULE
B16: Unit Typology | C16: Description / Occupancy | D16: Unit Carpet Area (sq.ft) | E16: No. of Units | F16: Total Beds | G16: Target Rent / Bed / Mo (₹) | H16: Beds / Unit (input)
B17: Type A: Single Micro-Studio Pod | C17: Private Studio with En-Suite Pod & Murphy Bed | D17: 260 | E17: 20 | F17: =E17*H17 | G17: 22000 | H17: 1
B18: Type B: Twin Sharing Suite Pod | C18: Dual Pod Cluster with Acoustically Separated Beds | D18: 340 | E18: 16 | F18: =E18*H18 | G18: 15500 | H18: 2
B19: Type C: Executive / Quad Suite | C19: Premium 4-Bed Co-Living Suite for Tech Groups | D19: 480 | E19: 4 | F19: =E19*H19 | G19: 13000 | H19: 4
B20: TOTALS / WEIGHTED AVERAGE | C20: Fully Furnished Turnkey Micro-Housing Pods | D20: =SUMPRODUCT(D17:D19, E17:E19)/E20 | E20: =SUM(E17:E19) | F20: =SUM(F17:F19) | G20: =SUMPRODUCT(F17:F19, G17:G19)/F20
B22: 1.3 COMPLETE 7-TIER SPACE PROGRAM & AREA ALLOCATION
B23: Category / Zone | C23: Spaces & Functional Components Included | D23: Level Allocation | E23: Area (sq.ft) | F23: % of Covered BUA
B24: 1. Arrival & Administration | C24: Ground Entry Portico, Express Elevator Core, Rooftop Lobby, Concierge, FM Office, Smart Parcel Room | D24: Ground & Level 5 | E24: 1500 | F24: =E24/E30
B25: 2. Community Core (Work & Social) | C25: Sky-Lounge, Co-Working Hub, Zoom Pods (x3), Conference Room, Barista Station, Community Kitchen & Dining | D25: Level 5 & 6 | E25: 4500 | F25: =E25/E30
B26: 3. Wellness & Recreation | C26: Fitness Center/Gym, Games Lounge (PS5/Billiards), Library & Quiet Focus Nook, Indoor Yoga Studio | D26: Level 5 & 6 | E26: 3000 | F26: =E26/E30
B27: 4. Residential Clusters & Sky-Streets | C27: Naturally Ventilated Sky-Streets (Corridors), Cluster Breakout Front-Porches, Communal Laundromat, Potting Station | D27: Level 5 & 6 | E27: 6000 | F27: =E27/E30
B28: 5. Private Living Units | C28: 20 Single Pods, 16 Twin Pods, 4 Quad Suites (40 Pods total with Turnkey En-Suite FRP Bathrooms) | D28: Level 5 & 6 | E28: 12500 | F28: =E28/E30
B29: 6. Back-of-House (BOH) & MEP | C29: 180mm Raised Floor Plenum, Hydropneumatic Pumps, MBR Greywater Plant, Solar Inverter Room, Server & Substation | D29: Level 5 & Services | E29: 2500 | F29: =E29/E30
B30: TOTAL COVERED BUILT-UP AREA (BUA) | C30: Enclosed Dry-Construction LGSF Structure (Loaded onto TG-bPASS / TDR) | D30: 2 Floors | E30: =SUM(E24:E29) | F30: =SUM(F24:F29)
B31: 7. Outdoor & Bioclimatic Terraces | C31: The Sky-Plaza Courtyard, Acrylic Pickleball / Multi-Sport Court, Hydroponic Urban Farm, Sunset BBQ & Viewing Deck | D31: Level 5 & 6 Open Decks | E31: 24000 | F31: Open Deck
B32: TOTAL ACTIVE ROOFTOP SPACE | C32: Total Enclosed BUA + Usable Open Terraces | D32: Comprehensive | E32: =E30+E31 | F32: -

Sheet 2. CPM Schedule & CapEx
C2: CPM PROJECT SCHEDULE & INSTITUTIONAL CAPEX BOQ
C3: LGSF + Bison Panel + Rockwool Infill | 100% Indian Supply Chain (Tata, NCL, Visaka, Saint-Gobain)
C5: 2.1 CPM 16-WEEK MASTER PROJECT SCHEDULE (72-HOUR CRANE LOGISTICS)
B6: Phase | C6: Activity / Milestone Name | D6: Detailed Scope & Execution Methodology | E6: Start Wk | F6: End Wk | G6: Duration | H6: Predecessor | I6: Critical Path?
B7: P1 | C7: Statutory Approvals & Structural Audit | D7: TG-bPASS filing, Non-destructive RCC column testing, Structural engineer certification, Fire NOC | E7: 1 | F7: 4 | G7: 4 Weeks | H7: None | I7: YES (Critical)
B8: P2 | C8: Offsite Factory Manufacturing | D8: LGSF precision cold-rolling (Tata G550), Bison panel CNC precutting, Modular FRP bathroom fabrication | E8: 3 | F8: 8 | G8: 6 Weeks | H8: P1 Approval | I8: YES (Critical)
B9: P3 | C9: Rooftop Substructure Preparation | D9: Core-drilling existing RCC columns, Hilti HIT-RE 500 V4 chemical anchoring, 25mm Neoprene pad leveling | E9: 7 | F9: 9 | G9: 2 Weeks | H9: P1, P2 | I9: YES (Critical)
B10: P4 | C10: Weekend Crane Erection Window | D10: 72-Hour continuous weekend road closure; 200-ton telescopic crane hoisting steel bundles & bathroom pods | E10: 9 | F10: 10 | G10: 72 Hours | H10: P3 Ready | I10: YES (Critical)
B11: P5 | C11: Envelope, Decking & MEP Rough-Ins | D11: NCL Bison 16mm floor decking, Visaka exterior siding, Rockwool infill, Hydropneumatic & vacuum plumbing | E11: 10 | F11: 13 | G11: 3 Weeks | H11: P4 Lift | I11: YES (Critical)
B12: P6 | C12: Interior Fitout & Commissioning | D12: Kinematic Murphy beds, Co-working furniture, Pickleball court acrylic laying, MBR testing, Handover | E12: 13 | F12: 16 | G12: 3 Weeks | H12: P5 Envelope | I12: YES (Critical)
C14: 2.2 INSTITUTIONAL BILL OF QUANTITIES (HARD & SOFT COSTS)
B15: S.No | C15: Trade / Cost Component | D15: Material Specification & Industrial Benchmark | E15: Basis / Driver | F15: Qty / Basis | G15: Rate (₹) | H15: Total Amount (₹) | I15: % of CapEx
B16: 1 | C16: Substructure Anchoring System | D16: Hilti HIT-RE 500 V4 injection mortar + 8.8 grade anchor studs to host RCC columns | E16: Per sq.ft BUA | F16: ='1. Space Program'!E30 | G16: 145 | H16: =F16*G16 | I16: =H16/$H$30
B17: 2 | C17: Acoustic Decoupling Pads | D17: 25mm Calibrated Neoprene / Sylomer elastomeric base isolators under all LGSF tracks | E17: Per sq.ft BUA | F17: ='1. Space Program'!E30 | G17: 40 | H17: =F17*G17 | I17: =H17/$H$30
B18: 3 | C18: LGSF Superstructure Framing | D18: Tata BlueScope / Everest G550 high-tensile cold-formed steel (Framing, trusses, joists) | E18: Per sq.ft BUA | F18: ='1. Space Program'!E30 | G18: 640 | H18: =F18*G18 | I18: =H18/$H$30
B19: 4 | C19: Floor Decking & Acoustic Underlay | D19: 16mm NCL Bison cement-bonded particle board + 5mm acoustic mat + Heavy-duty SPC vinyl | E19: Per sq.ft BUA | F19: ='1. Space Program'!E30 | G19: 210 | H19: =F19*G19 | I19: =H19/$H$30
B20: 5 | C20: Exterior Cladding & Weatherproofing | D20: 12mm Visaka FCB + Tyvek weather-barrier + Polyurethane UV-resistant protective facade | E20: Per sq.ft BUA | F20: ='1. Space Program'!E30 | G20: 230 | H20: =F20*G20 | I20: =H20/$H$30
B21: 6 | C21: Internal Partitions & Acoustic Walls | D21: Gyproc double drywall + 64kg/m³ Rockwool insulation (STC 52 acoustic rating) | E21: Per sq.ft BUA | F21: ='1. Space Program'!E30 | G21: 175 | H21: =F21*G21 | I21: =H21/$H$30
B22: 7 | C22: Turnkey FRP Modular Bathroom Pods | D22: 40 Factory prefabricated composite bathroom pods with Jaquar/Kohler sanitaryware | E22: Per Unit | F22: ='1. Space Program'!E20 | G22: 180000 | H22: =F22*G22 | I22: =H22/$H$30
B23: 8 | C23: Kinematic Private Pod Fitout | D23: Integrated Murphy beds, acoustic sliding partitions, modular wardrobes, study workstations | E23: Per Unit | F23: ='1. Space Program'!E20 | G23: 160000 | H23: =F23*G23 | I23: =H23/$H$30
B24: 9 | C24: Community Core & Wellness Fitout | D24: Co-working hot-desks, Commercial kitchen islands, Gym equipment, PS5 game lounge AV | E24: Lump Sum | F24: 1 | G24: 5500000 | H24: =F24*G24 | I24: =H24/$H$30
B25: 10 | C25: Outdoor Hardscaping & Recreation | D25: Acrylic Pickleball court, Composite timber decking, Sky-Plaza pergolas, Hydroponic farm | E25: Per sq.ft Deck | F25: ='1. Space Program'!E31 | G25: 270 | H25: =F25*G25 | I25: =H25/$H$30
B26: 11 | C26: MEP Infrastructure & Glass Lift | D26: Hydropneumatic booster system, Vacuum drainage, MBR greywater plant, Scenic glass elevator | E26: Lump Sum | F26: 1 | G26: 9500000 | H26: =F26*G26 | I26: =H26/$H$30
B27: 12 | C27: BIPV Solar Canopy & Blue Roof | D27: 100 kWp Rooftop Solar Pergola canopy + Stormwater retention attenuation blue-roof cells | E27: Lump Sum | F27: 1 | G27: 5200000 | H27: =F27*G27 | I27: =H27/$H$30
B28: 13 | C28: High-Performance Glazing | D28: Saint-Gobain Planitherm Low-E DGU acoustic insulated double glazing | E28: Per sq.ft BUA | F28: ='1. Space Program'!E30 | G28: 95 | H28: =F28*G28 | I28: =H28/$H$30
B29: 14 | C29: Soft Costs, PMC, Statutories & Contingency | D29: Architecture, Structural vetting, TG-bPASS fees, PMC supervision, Fire NOC, 5% Contingency | E29: Lump Sum | F29: 1 | G29: 11500000 | H29: =F29*G29 | I29: =H29/$H$30
C30: TOTAL TURNKEY BASE CONSTRUCTION CAPEX | D30: Complete EPC Turnkey Delivery (Excl. External TDR) | E30: - | F30: - | G30: - | H30: =SUM(H16:H29) | I30: =SUM(I16:I29)
C32: CapEx per sq.ft of Enclosed BUA (30,000 sq.ft) | D32: =H30/'1. Space Program'!E30
C33: CapEx per Pod Unit (40 Units Turnkey) | D33: =H30/'1. Space Program'!E20
C34: CapEx per Bed (68 Total Beds) | D34: =H30/'1. Space Program'!F20

Sheet 3. Model 1 (In-House TDR)
B2: FINANCIAL MODEL 1: IN-HOUSE TDR / UNUTILIZED FAR (HOST OWNED)
B3: Joint Venture Structure: Host Contributes Roof Rights & TDR | Developer Injects Equity & Arranges Debt
B5: 3.1 CAPITAL STACK & JV UNDERWRITING ASSUMPTIONS | F5: 3.2 OPERATIONAL REVENUE & OPEX DRIVERS
B6: Financial Parameter | C6: Value | D6: Notes / Source | F6: Operational Parameter | G6: Value | H6: Notes / Justification
B7: External TDR Acquisition Cost | C7: 0 | D7: In-House TDR owned by Host | F7: Total Bed Capacity | G7: ='1. Space Program'!F20 | H7: 68 Beds across 40 Pods
B8: Base Construction CapEx (EPC) | C8: ='2. CPM Schedule & CapEx'!H30 | D8: From BOQ Tab | F8: Blended Monthly Rent / Bed | G8: ='1. Space Program'!G20 | H8: Weighted Avg from Unit Mix
B9: Total Project CapEx | C9: =C7+C8 | D9: Base Hard + Soft Costs | F9: Gross Potential Bed Rental / Month | G9: =G7*G8 | H9: Full Occupancy Base
B10: Senior Debt Financing (LTV %) | C10: 0.65 | D10: 65% Commercial Debt | F10: Monthly Ancillary Revenues | G10: 350000 | H10: Co-Working passes, Sky-Plaza events, Pickleball, Cafe
B11: Sponsor / Developer Equity % | C11: =1-C10 | D11: 35% Equity Infusion | F11: Annual Gross Potential Revenue (GPR) | G11: =(G9+G10)*12 | H11: 100% Occupancy Run-Rate
B12: Total Senior Loan Amount | C12: =C9*C10 | D12: Bank Construction Facility | F12: Year 1 Lease-up Occupancy % | G12: 0.8 | H12: Initial stabilization period
B13: Total Developer Equity Required | C13: =C9*C11 | D13: Developer Pocket Outflow | F13: Stabilized Occupancy % (Yr 2+) | G13: 0.92 | H13: 92% Long-term Occupancy
B14: Annual Loan Interest Rate (p.a.) | C14: 0.0975 | D14: 9.75% CRE Priority Green Infill Rate | F14: Bi-Annual Rental Escalation % | G14: 0.05 | H14: 5.0% Rent Escalation every 2 Yrs
B15: Loan Amortization Tenure | C15: 15 | D15: 15-Year Commercial Term Loan | F15: Operating Expenses (OpEx % of EGR) | G15: 0.28 | H15: 28% (Efficient Single-Site FM, WiFi, Utilities)
B16: Developer (GP) JV Share % | C16: 0.6 | D16: 60% Share of Free Cash Flow | F16: Exit Cap Rate (Terminal Valuation) | G16: 0.085 | H16: 8.50% Capitalization Rate
B17: Host Owner (LP) JV Share % | C17: =1-C16 | D17: 40% Passive Royalty Share
B19: 3.3 10-YEAR ANNUAL CASH FLOW PROFORMA STATEMENT
B20: Line Item / Metric | C20: Year 0 (Const.) | D20: Year 1 | E20: Year 2 | F20: Year 3 | G20: Year 4 | H20: Year 5 | I20: Year 6 | J20: Year 7 | K20: Year 8 | L20: Year 9 | M20: Year 10
B21: Occupancy Rate (%) | C21: 0 | D21: =$G$12 | E21: =$G$13 | F21: =$G$13 | G21: =$G$13 | H21: =$G$13 | I21: =$G$13 | J21: =$G$13 | K21: =$G$13 | L21: =$G$13 | ... N21: =$G$13
B22: Gross Potential Revenue (GPR) | C22: 0 | D22: =$G$11*(1+$G$14)^INT(0/2) | E22: =$G$11*(1+$G$14)^INT(1/2) | F22: =$G$11*(1+$G$14)^INT(2/2) | G22: =$G$11*(1+$G$14)^INT(3/2) | H22: =$G$11*(1+$G$14)^INT(4/2) | I22: =$G$11*(1+$G$14)^INT(5/2) | J22: =$G$11*(1+$G$14)^INT(6/2) | K22: =$G$11*(1+$G$14)^INT(7/2) | L22: =$G$11*(1+$G$14)^INT(8/2) | M22: =$G$11*(1+$G$14)^INT(9/2)
B23: Effective Gross Revenue (EGR) | C23: 0 | D23: =D22*D21 | E23: =E22*E21 | F23: =F22*F21 | G23: =G22*G21 | H23: =H22*H21 | I23: =I22*I21 | J23: =J22*J21 | K23: =K22*K21 | ... M23: =M22*M21
B24: Operating Expenses (OpEx @ 28%) | C24: 0 | D24: =-D23*$G$15 | E24: =-E23*$G$15 | F24: =-F23*$G$15 | G24: =-G23*$G$15 | H24: =-H23*$G$15 | I24: =-I23*$G$15 | J24: =-J23*$G$15 | K24: =-K23*$G$15 | ... M24: =-M23*$G$15
B25: Net Operating Income (NOI) | C25: 0 | D25: =D23+D24 | E25: =E23+E24 | F25: =F23+F24 | G25: =G23+G24 | H25: =H23+H24 | I25: =I23+I24 | J25: =J23+J24 | K25: =K23+K24 | ... M25: =M23+M24
B26: Senior Debt Service (15-Yr Amortizing P&I) | C26: 0 | D26: =-PMT($C$14, $C$15, $C$12) | E26: =-PMT($C$14, $C$15, $C$12) | F26: =-PMT($C$14, $C$15, $C$12) | G26: =-PMT($C$14, $C$15, $C$12) | H26: =-PMT($C$14, $C$15, $C$12) | I26: =-PMT($C$14, $C$15, $C$12) | J26: =-PMT($C$14, $C$15, $C$12) | K26: =-PMT($C$14, $C$15, $C$12) | ... M26: =-PMT($C$14, $C$15, $C$12)
B27: Levered Free Cash Flow (to JV Partners) | C27: =-$C$13 | D27: =D25-D26 | E27: =E25-E26 | F27: =F25-F26 | G27: =G25-G26 | H27: =H25-H26 | I27: =I25-I26 | J27: =J25-J26 | K27: =K25-K26 | L27: =L25-L26 | M27: =M25-M26+$C$47
B28: Unlevered Free Cash Flow (Project Level) | C28: =-$C$9 | D28: =D25 | E28: =E25 | F28: =F25 | G28: =G25 | H28: =H25 | I28: =I25 | J28: =J25 | K28: =K25 | L28: =L25 | M28: =M25+$C$45
B30: 3.4 JOINT VENTURE WATERFALL CASH FLOW ALLOCATION
B31: Line Item / Metric | C31: Year 0 (Const.) | D31: Year 1 | E31: Year 2 | F31: Year 3 | G31: Year 4 | H31: Year 5 | I31: Year 6 | J31: Year 7 | K31: Year 8 | L31: Year 9 | M31: Year 10
B32: Developer (GP - 60% Free Cash Flow) | C32: =-$C$13 | D32: =D27*$C$16 | E32: =E27*$C$16 | F32: =F27*$C$16 | G32: =G27*$C$16 | H32: =H27*$C$16 | I32: =I27*$C$16 | J32: =J27*$C$16 | K32: =K27*$C$16 | ... M32: =M27*$C$16
B33: Host Owner (LP - 40% Free Cash Flow) | C33: 0 | D33: =D27*$C$17 | E33: =E27*$C$17 | F33: =F27*$C$17 | G33: =G27*$C$17 | H33: =H27*$C$17 | I33: =I27*$C$17 | J33: =J27*$C$17 | K33: =K27*$C$17 | ... M33: =M27*$C$17
B34: Host Cumulative Cash Realized | C34: 0 | D34: =D33 | E34: =D34+E33 | F34: =E34+F33 | G34: =F34+G33 | H34: =G34+H33 | I34: =H34+I33 | J34: =I34+J33 | K34: =J34+K33 | L34: =K34+L33 | ... N34: =M34+N33
B36: 3.5 RETURN METRICS & DEBT COVENANTS | F36: 3.6 10-YEAR SENIOR DEBT AMORTIZATION SCHEDULE (15-YR BASIS)
B37: Key Return / Banking Metric | C37: Value | D37: Benchmark / Interpretation | F37: Year | G37: Beginning Balance (₹) | H37: Annual Payment (₹) | I37: Interest Paid (₹) | J37: Principal Paid (₹) | K37: Ending Balance (₹) | L37: DSCR (x)
B38: Unlevered Project IRR | C38: =IRR(C28:M28) | D38: Project Return pre-leverage
B39: Levered Project IRR | C39: =IRR(C27:M27) | D39: Return on Total Equity Invested | F39: Year 1 | G39: =$C$12 | H39: =-D$26 | I39: =G39*$C$14 | J39: =H39+I39 | K39: =G39+J39 | L39: =D$25/D$26
B40: Developer (GP) Equity IRR | C40: =IRR(C32:M32) | D40: Return on Developer Pocket Capital | F40: Year 2 | G40: =K39 | H40: =-E$26 | I40: =G40*$C$14 | J40: =H40+I40 | K40: =G40+J40 | L40: =E$25/E$26
B41: Developer Equity Multiple (MOIC) | C41: =SUM(D32:M32)/(-C32) | D41: Total Cash Returned / Equity | F41: Year 3 | G41: =K40 | H41: =-F$26 | I41: =G41*$C$14 | J41: =H41+I41 | K41: =G41+J41 | L41: =F$25/F$26
B42: 10-Year Cumulative Host Payout | C42: =N34 | D42: Passive Royalty Earnings | F42: Year 4 | G42: =K41 | H42: =-G$26 | I42: =G42*$C$14 | J42: =H42+I42 | K42: =G42+J42 | L42: =G$25/G$26
B43: Year 2 Stabilized Yield on Cost | C43: =E25/C9 | D43: Stabilized NOI / Total CapEx | F43: Year 5 | G43: =K42 | H43: =-H$26 | I43: =G43*$C$14 | J43: =H43+I43 | K43: =G43+J43 | L43: =H$25/H$26
B44: Year 2 DSCR (Debt Coverage) | C44: =E25/E26 | D44: Min Banking Threshold: 1.25x | F44: Year 6 | G44: =K43 | H44: =-I$26 | I44: =G44*$C$14 | J44: =H44+I44 | K44: =G44+J44 | L44: =I$25/I$26
B45: Terminal Valuation (Yr 10 Exit @ 8.5% Cap) | C45: =(M25*(1+G14))/G16 | D45: Gross Asset Value at Exit | F45: Year 7 | G45: =K44 | H45: =-J$26 | I45: =G45*$C$14 | J45: =H45+I45 | K45: =G45+J45 | L45: =J$25/J$26
...

Sheet 4. Model 2 (External TDR)
B2: FINANCIAL MODEL 2: EXTERNAL TDR PURCHASE (HYDERABAD MARKET PURCHASE)
B3: Joint Venture Structure: Developer Funds External TDR Acquisition + Base Construction | 75/25 JV Split
B5: 4.1 CAPITAL STACK & JV UNDERWRITING ASSUMPTIONS | F5: 4.2 OPERATIONAL REVENUE & OPEX DRIVERS
B6: Financial Parameter | C6: Value | D6: Notes / Source | F6: Operational Parameter | G6: Value | H6: Notes / Justification
B7: TDR Market Certificate Rate (₹/sq.ft BUA) | C7: 150 | D7: TSPA / Bandlaguda Receiving Zone (2026) | F7: Total Bed Capacity | G7: ='1. Space Program'!F20 | H7: 68 Beds across 40 Pods
B8: Total External TDR Acquisition Cost | C8: ='1. Space Program'!E30*C7 | D8: 30,000 sq.ft BUA * ₹1,200 | F8: Blended Monthly Rent / Bed | G8: ='1. Space Program'!G20 | H8: Weighted Avg from Unit Mix
B9: Base Construction CapEx (EPC) | C9: ='2. CPM Schedule & CapEx'!H30 | D9: From BOQ Tab | F9: Gross Potential Bed Rental / Month | G9: =G7*G8 | H9: Full Occupancy Base
B10: Total Turnkey Project CapEx | C10: =C8+C9 | D10: TDR + Hard + Soft Costs | F10: Monthly Ancillary Revenues | G10: 350000 | H10: Co-Working passes, Sky-Plaza events, Pickleball, Cafe
B11: Senior Debt Financing (LTV %) | C11: 0.65 | D11: 65% Commercial Debt | F11: Annual Gross Potential Revenue (GPR) | G11: =(G9+G10)*12 | H11: 100% Occupancy Run-Rate
B12: Sponsor / Developer Equity % | C12: =1-C11 | D12: 35% Equity Infusion | F12: Year 1 Lease-up Occupancy % | G12: 0.8 | H12: Initial stabilization period
B13: Total Senior Loan Amount | C13: =C10*C11 | D13: Bank Construction Facility | F13: Stabilized Occupancy % (Yr 2+) | G13: 0.92 | H13: 92% Long-term Occupancy
B14: Total Developer Equity Required | C14: =C10*C12 | D14: Developer Pocket Outflow | F14: Bi-Annual Rental Escalation % | G14: 0.05 | H14: 5.0% Rent Escalation every 2 Yrs
B15: Annual Loan Interest Rate (p.a.) | C15: 0.0975 | D15: 9.75% CRE Priority Green Infill Rate | F15: Operating Expenses (OpEx % of EGR) | G15: 0.28 | H15: 28% (Efficient Single-Site FM, WiFi, Utilities)
B16: Loan Amortization Tenure | C16: 15 | D16: 15-Year Commercial Term Loan | F16: Exit Cap Rate (Terminal Valuation) | G16: 0.085 | H16: 8.50% Capitalization Rate
B17: Developer (GP) JV Share % | C17: 0.75 | D17: 75% Share (Compensating TDR Outflow)
B18: Host Owner (LP) JV Share % | C18: =1-C17 | D18: 25% Passive Royalty Share
B20: 4.3 10-YEAR ANNUAL CASH FLOW PROFORMA STATEMENT
B21: Line Item / Metric | C21: Year 0 (Const.) | D21: Year 1 | E21: Year 2 | F21: Year 3 | G21: Year 4 | H21: Year 5 | I21: Year 6 | J21: Year 7 | K21: Year 8 | L21: Year 9 | M21: Year 10
B22: Occupancy Rate (%) | C22: 0 | D22: =$G$12 | E22: =$G$13 | F22: =$G$13 | G22: =$G$13 | H22: =$G$13 | I22: =$G$13 | J22: =$G$13 | K22: =$G$13 | L22: =$G$13 | ... N22: =$G$13
B23: Gross Potential Revenue (GPR) | C23: 0 | D23: =$G$11*(1+$G$14)^INT(0/2) | E23: =$G$11*(1+$G$14)^INT(1/2) | F23: =$G$11*(1+$G$14)^INT(2/2) | G23: =$G$11*(1+$G$14)^INT(3/2) | H23: =$G$11*(1+$G$14)^INT(4/2) | I23: =$G$11*(1+$G$14)^INT(5/2) | J23: =$G$11*(1+$G$14)^INT(6/2) | K23: =$G$11*(1+$G$14)^INT(7/2) | L23: =$G$11*(1+$G$14)^INT(8/2) | M23: =$G$11*(1+$G$14)^INT(9/2)
B24: Effective Gross Revenue (EGR) | C24: 0 | D24: =D23*D22 | E24: =E23*E22 | F24: =F23*F22 | G24: =G23*G22 | H24: =H23*H22 | I24: =I23*I22 | J24: =J23*J22 | K24: =K23*K22 | ... M24: =M23*M22
B25: Operating Expenses (OpEx @ 28%) | C25: 0 | D25: =-D24*$G$15 | E25: =-E24*$G$15 | F25: =-F24*$G$15 | G25: =-G24*$G$15 | H25: =-H24*$G$15 | I25: =-I24*$G$15 | J25: =-J24*$G$15 | K25: =-K24*$G$15 | ... M25: =-M24*$G$15
B26: Net Operating Income (NOI) | C26: 0 | D26: =D24+D25 | E26: =E24+E25 | F26: =F24+F25 | G26: =G24+G25 | H26: =H24+H25 | I26: =I24+I25 | J26: =J24+J25 | K26: =K24+K25 | ... M26: =M24+M25
B27: Senior Debt Service (15-Yr Amortizing P&I) | C27: 0 | D27: =-PMT($C$15, $C$16, $C$13) | E27: =-PMT($C$15, $C$16, $C$13) | F27: =-PMT($C$15, $C$16, $C$13) | G27: =-PMT($C$15, $C$16, $C$13) | H27: =-PMT($C$15, $C$16, $C$13) | I27: =-PMT($C$15, $C$16, $C$13) | J27: =-PMT($C$15, $C$16, $C$13) | K27: =-PMT($C$15, $C$16, $C$13) | ... M27: =-PMT($C$15, $C$16, $C$13)
B28: Levered Free Cash Flow (to JV Partners) | C28: =-$C$14 | D28: =D26-D27 | E28: =E26-E27 | F28: =F26-F27 | G28: =G26-G27 | H28: =H26-H27 | I28: =I26-I27 | J28: =J26-J27 | K28: =K26-K27 | L28: =L26-L27 | M28: =M26-M27+$C$48
B29: Unlevered Free Cash Flow (Project Level) | C29: =-$C$10 | D29: =D26 | E29: =E26 | F29: =F26 | G29: =G26 | H29: =H26 | I29: =I26 | J29: =J26 | K29: =K26 | L29: =L26 | M29: =M26+$C$46
B31: 4.4 JOINT VENTURE WATERFALL CASH FLOW ALLOCATION
B32: Line Item / Metric | C32: Year 0 (Const.) | D32: Year 1 | E32: Year 2 | F32: Year 3 | G32: Year 4 | H32: Year 5 | I32: Year 6 | J32: Year 7 | K32: Year 8 | L32: Year 9 | M32: Year 10
B33: Developer (GP - 75% Free Cash Flow) | C33: =-$C$14 | D33: =D28*$C$17 | E33: =E28*$C$17 | F33: =F28*$C$17 | G33: =G28*$C$17 | H33: =H28*$C$17 | I33: =I28*$C$17 | J33: =J28*$C$17 | K33: =K28*$C$17 | ... M33: =M28*$C$17
B34: Host Owner (LP - 25% Free Cash Flow) | C34: 0 | D34: =D28*$C$18 | E34: =E28*$C$18 | F34: =F28*$C$18 | G34: =G28*$C$18 | H34: =H28*$C$18 | I34: =I28*$C$18 | J34: =J28*$C$18 | K34: =K28*$C$18 | ... M34: =M28*$C$18
B35: Host Cumulative Cash Realized | C35: 0 | D35: =D34 | E35: =D35+E34 | F35: =E35+F34 | G35: =F35+G34 | H35: =G35+H34 | I35: =H35+I34 | J35: =I35+J34 | K35: =J35+K34 | L35: =K35+L34 | ... N35: =M35+N34
B37: 4.5 RETURN METRICS & DEBT COVENANTS | F37: 4.6 10-YEAR SENIOR DEBT AMORTIZATION SCHEDULE (15-YR BASIS)
B38: Key Return / Banking Metric | C38: Value | D38: Benchmark / Interpretation | F38: Year | G38: Beginning Balance (₹) | H38: Annual Payment (₹) | I38: Interest Paid (₹) | J38: Principal Paid (₹) | K38: Ending Balance (₹) | L38: DSCR (x)
B39: Unlevered Project IRR | C39: =IRR(C29:M29) | D39: Project Return pre-leverage
B40: Levered Project IRR | C40: =IRR(C28:M28) | D40: Return on Total Equity Invested | F40: Year 1 | G40: =$C$13 | H40: =-D$27 | I40: =G40*$C$15 | J40: =H40+I40 | K40: =G40+J40 | L40: =D$26/D$27
B41: Developer (GP) Equity IRR | C41: =IRR(C33:M33) | D41: Return on Developer Pocket Capital | F41: Year 2 | G41: =K40 | H41: =-E$27 | I41: =G41*$C$15 | J41: =H41+I41 | K41: =G41+J41 | L41: =E$26/E$27
B42: Developer Equity Multiple (MOIC) | C42: =SUM(D33:M33)/(-C33) | D42: Total Cash Returned / Equity | F42: Year 3 | G42: =K41 | H42: =-F$27 | I42: =G42*$C$15 | J42: =H42+I42 | K42: =G42+J42 | L42: =F$26/F$27
B43: 10-Year Cumulative Host Payout | C43: =N35 | D43: Passive Royalty Earnings | F43: Year 4 | G43: =K42 | H43: =-G$27 | I43: =G43*$C$15 | J43: =H43+I43 | K43: =G43+J43 | L43: =G$26/G$27
B44: Year 2 Stabilized Yield on Cost | C44: =E26/C10 | D44: Stabilized NOI / Total CapEx | F44: Year 5 | G44: =K43 | H44: =-H$27 | I44: =G44*$C$15 | J44: =H44+I44 | K44: =G44+J44 | L44: =H$26/H$27
B45: Year 2 DSCR (Debt Coverage) | C45: =E26/E27 | D45: Min Banking Threshold: 1.25x | F45: Year 6 | G45: =K44 | H45: =-I$27 | I45: =G45*$C$15 | J45: =H45+I45 | K45: =G45+J45 | L45: =I$26/I$27
...

Sheet 5. Opportunity Cost
B2: OPPORTUNITY COST & SENSITIVITY STRESS-TEST MATRIX
B3: Host Decision Analysis: Evaluating Unused Potential vs Outright TDR Sale vs Vertical Extension JV
B5: 5.1 3-WAY HOST ASSET MONETIZATION DECISION MATRIX
B6: Financial Metric / Parameter | C6: Scenario A: Do Nothing | D6: Scenario B: Outright TDR Sale | E6: Scenario C: Vertical Extension JV (Model 1)
B7: Immediate Gross Cash Realization | C7: 0 | D7: ='4. Model 2 (External TDR)'!C8 | E7: 0
B8: Capital Gains / Transaction Tax (20%) | C8: 0 | D8: =-D7*$G$8 | E8: 0 | F8: Tax Rate Input: | G8: 0.2
B9: Net Upfront Cash in Hand | C9: =C7+C8 | D9: =D7+D8 | E9: =E7+E8
B10: Ongoing Rooftop Maintenance Drag (10 Yrs) | C10: -1850000 | D10: 0 | E10: 0
B11: 10-Year Cumulative Operating Cash Flow | C11: 0 | D11: 0 | E11: ='3. Model 1 (In-House TDR)'!C42
B12: Memo: Terminal Exit Value (Host Share) — already included above | C12: 0 | D12: 0 | E12: ='3. Model 1 (In-House TDR)'!C47*'3. Model 1 (In-House TDR)'!C17
B13: 10-YEAR TOTAL NET WEALTH CREATED | C13: =C9+C10+C11 | D13: =D9+D10+D11 | E13: =E9+E10+E11
B14: Wealth Creation Multiplier vs TDR Sale | C14: =C13/$D$13 | D14: =D13/$D$13 | E14: =E13/$D$13
B17: 5.2 2-WAY SENSITIVITY ANALYSIS: LEVERED OPERATING-CF IRR vs OCCUPANCY & RENT (MODEL 1, excl. Year-10 exit — see note below grid)
B18: Blended Rent / Bed (₹) ↓ | Occupancy → | C18: 80.0% | D18: 85.0% | E18: 90.0% | F18: 92.0% (Base) | G18: 95.0%
B19: ₹18,000 | C19: =N28 | D19: =N29 | E19: =N30 | F19: =N31 | G19: =N32
B20: ₹20,000 | C20: =N33 | D20: =N34 | E20: =N35 | F20: =N36 | G20: =N37
B21: ₹22,000 | C21: =N38 | D21: =N39 | E21: =N40 | F21: =N41 | G21: =N42
B22: ₹24,000 | C22: =N43 | D22: =N44 | E22: =N45 | F22: =N46 | G22: =N47
B23: ₹26,000 | C23: =N48 | D23: =N49 | E23: =N50 | F23: =N51 | G23: =N52
B26: 5.3 SENSITIVITY ENGINE — FULL 10-YEAR CASH-FLOW RECONSTRUCTION (AUDITABLE)
B27: Rent / Occupancy Scenario | C27: Year 0 | D27: Year 1 | E27: Year 2 | F27: Year 3 | G27: Year 4 | H27: Year 5 | I27: Year 6 | J27: Year 7 | K27: Year 8 | L27: Year 9 | M27: Year 10 | N27: Levered IRR (Op. CF only, excl. exit) | P27: Rent Input (Rs./bed/mo) | Q27: Occupancy Input
B28: ="Rent ₹"&TEXT(P28,"#,##0")&" @ "&TEXT(Q28,"0%")&" occ." | C28: =-'3. Model 1 (In-House TDR)'!$C$13 | D28: =((((('3. Model 1 (In-House TDR)'!$G$7*$P28*12)+('3. Model 1 (In-House TDR)'!$G$10*12))*(1+'3. Model 1 (In-House TDR)'!$G$14)^INT((1-1)/2))*'3. Model 1 (In-House TDR)'!$G$12)*(1-'3. Model 1 (In-House TDR)'!$G$15))-'3. Model 1 (In-House TDR)'!$D$26 | E28: =((((('3. Model 1 (In-House TDR)'!$G$7*$P28*12)+('3. Model 1 (In-House TDR)'!$G$10*12))*(1+'3. Model 1 (In-House TDR)'!$G$14)^INT((2-1)/2))*$Q28)*(1-'3. Model 1 (In-House TDR)'!$G$15))-'3. Model 1 (In-House TDR)'!$D$26 | F28: =((((('3. Model 1 (In-House TDR)'!$G$7*$P28*12)+('3. Model 1 (In-House TDR)'!$G$10*12))*(1+'3. Model 1 (In-House TDR)'!$G$14)^INT((3-1)/2))*$Q28)*(1-'3. Model 1 (In-House TDR)'!$G$15))-'3. Model 1 (In-House TDR)'!$D$26 | G28: =((((('3. Model 1 (In-House TDR)'!$G$7*$P28*12)+('3. Model 1 (In-House TDR)'!$G$10*12))*(1+'3. Model 1 (In-House TDR)'!$G$14)^INT((4-1)/2))*$Q28)*(1-'3. Model 1 (In-House TDR)'!$G$15))-'3. Model 1 (In-House TDR)'!$D$26 | H28: =((((('3. Model 1 (In-House TDR)'!$G$7*$P28*12)+('3. Model 1 (In-House TDR)'!$G$10*12))*(1+'3. Model 1 (In-House TDR)'!$G$14)^INT((5-1)/2))*$Q28)*(1-'3. Model 1 (In-House TDR)'!$G$15))-'3. Model 1 (In-House TDR)'!$D$26 | I28: =((((('3. Model 1 (In-House TDR)'!$G$7*$P28*12)+('3. Model 1 (In-House TDR)'!$G$10*12))*(1+'3. Model 1 (In-House TDR)'!$G$14)^INT((6-1)/2))*$Q28)*(1-'3. Model 1 (In-House TDR)'!$G$15))-'3. Model 1 (In-House TDR)'!$D$26 | J28: =((((('3. Model 1 (In-House TDR)'!$G$7*$P28*12)+('3. Model 1 (In-House TDR)'!$G$10*12))*(1+'3. Model 1 (In-House TDR)'!$G$14)^INT((7-1)/2))*$Q28)*(1-'3. Model 1 (In-House TDR)'!$G$15))-'3. Model 1 (In-House TDR)'!$D$26 | K28: =((((('3. Model 1 (In-House TDR)'!$G$7*$P28*12)+('3. Model 1 (In-House TDR)'!$G$10*12))*(1+'3. Model 1 (In-House TDR)'!$G$14)^INT((8-1)/2))*$Q28)*(1-'3. Model 1 (In-House TDR)'!$G$15))-'3. Model 1 (In-House TDR)'!$D$26 | L28: =((((('3. Model 1 (In-House TDR)'!$G$7*$P28*12)+('3. Model 1 (In-House TDR)'!$G$10*12))*(1+'3. Model 1 (In-House TDR)'!$G$14)^INT((9-1)/2))*$Q28)*(1-'3. Model 1 (In-House TDR)'!$G$15))-'3. Model 1 (In-House TDR)'!$D$26 | M28: =((((('3. Model 1 (In-House TDR)'!$G$7*$P28*12)+('3. Model 1 (In-House TDR)'!$G$10*12))*(1+'3. Model 1 (In-House TDR)'!$G$14)^INT((10-1)/2))*$Q28)*(1-'3. Model 1 (In-House TDR)'!$G$15))-'3. Model 1 (In-House TDR)'!$D$26 | N28: =IRR(C28:M28) | P28: 18000 | Q28: 0.8
B29: ="Rent ₹"&TEXT(P29,"#,##0")&" @ "&TEXT(Q29,"0%")&" occ." | C29: =-'3. Model 1 (In-House TDR)'!$C$13 | D29: =((((('3. Model 1 (In-House TDR)'!$G$7*$P29*12)+('3. Model 1 (In-House TDR)'!$G$10*12))*(1+'3. Model 1 (In-House TDR)'!$G$14)^INT((1-1)/2))*'3. Model 1 (In-House TDR)'!$G$12)*(1-'3. Model 1 (In-House TDR)'!$G$15))-'3. Model 1 (In-House TDR)'!$D$26 | E29: =((((('3. Model 1 (In-House TDR)'!$G$7*$P29*12)+('3. Model 1 (In-House TDR)'!$G$10*12))*(1+'3. Model 1 (In-House TDR)'!$G$14)^INT((2-1)/2))*$Q29)*(1-'3. Model 1 (In-House TDR)'!$G$15))-'3. Model 1 (In-House TDR)'!$D$26 | F29: =((((('3. Model 1 (In-House TDR)'!$G$7*$P29*12)+('3. Model 1 (In-House TDR)'!$G$10*12))*(1+'3. Model 1 (In-House TDR)'!$G$14)^INT((3-1)/2))*$Q29)*(1-'3. Model 1 (In-House TDR)'!$G$15))-'3. Model 1 (In-House TDR)'!$D$26 | G29: =((((('3. Model 1 (In-House TDR)'!$G$7*$P29*12)+('3. Model 1 (In-House TDR)'!$G$10*12))*(1+'3. Model 1 (In-House TDR)'!$G$14)^INT((4-1)/2))*$Q29)*(1-'3. Model 1 (In-House TDR)'!$G$15))-'3. Model 1 (In-House TDR)'!$D$26 | H29: =((((('3. Model 1 (In-House TDR)'!$G$7*$P29*12)+('3. Model 1 (In-House TDR)'!$G$10*12))*(1+'3. Model 1 (In-House TDR)'!$G$14)^INT((5-1)/2))*$Q29)*(1-'3. Model 1 (In-House TDR)'!$G$15))-'3. Model 1 (In-House TDR)'!$D$26 | I29: =((((('3. Model 1 (In-House TDR)'!$G$7*$P29*12)+('3. Model 1 (In-House TDR)'!$G$10*12))*(1+'3. Model 1 (In-House TDR)'!$G$14)^INT((6-1)/2))*$Q29)*(1-'3. Model 1 (In-House TDR)'!$G$15))-'3. Model 1 (In-House TDR)'!$D$26 | J29: =((((('3. Model 1 (In-House TDR)'!$G$7*$P29*12)+('3. Model 1 (In-House TDR)'!$G$10*12))*(1+'3. Model 1 (In-House TDR)'!$G$14)^INT((7-1)/2))*$Q29)*(1-'3. Model 1 (In-House TDR)'!$G$15))-'3. Model 1 (In-House TDR)'!$D$26 | K29: =((((('3. Model 1 (In-House TDR)'!$G$7*$P29*12)+('3. Model 1 (In-House TDR)'!$G$10*12))*(1+'3. Model 1 (In-House TDR)'!$G$14)^INT((8-1)/2))*$Q29)*(1-'3. Model 1 (In-House TDR)'!$G$15))-'3. Model 1 (In-House TDR)'!$D$26 | L29: =((((('3. Model 1 (In-House TDR)'!$G$7*$P29*12)+('3. Model 1 (In-House TDR)'!$G$10*12))*(1+'3. Model 1 (In-House TDR)'!$G$14)^INT((9-1)/2))*$Q29)*(1-'3. Model 1 (In-House TDR)'!$G$15))-'3. Model 1 (In-House TDR)'!$D$26 | M29: =((((('3. Model 1 (In-House TDR)'!$G$7*$P29*12)+('3. Model 1 (In-House TDR)'!$G$10*12))*(1+'3. Model 1 (In-House TDR)'!$G$14)^INT((10-1)/2))*$Q29)*(1-'3. Model 1 (In-House TDR)'!$G$15))-'3. Model 1 (In-House TDR)'!$D$26 | N29: =IRR(C29:M29) | P29: 18000 | Q29: 0.85
B30: ="Rent ₹"&TEXT(P30,"#,##0")&" @ "&TEXT(Q30,"0%")&" occ." | C30: =-'3. Model 1 (In-House TDR)'!$C$13 | D30: =((((('3. Model 1 (In-House TDR)'!$G$7*$P30*12)+('3. Model 1 (In-House TDR)'!$G$10*12))*(1+'3. Model 1 (In-House TDR)'!$G$14)^INT((1-1)/2))*'3. Model 1 (In-House TDR)'!$G$12)*(1-'3. Model 1 (In-House TDR)'!$G$15))-'3. Model 1 (In-House TDR)'!$D$26 | E30: =((((('3. Model 1 (In-House TDR)'!$G$7*$P30*12)+('3. Model 1 (In-House TDR)'!$G$10*12))*(1+'3. Model 1 (In-House TDR)'!$G$14)^INT((2-1)/2))*$Q30)*(1-'3. Model 1 (In-House TDR)'!$G$15))-'3. Model 1 (In-House TDR)'!$D$26 | F30: =((((('3. Model 1 (In-House TDR)'!$G$7*$P30*12)+('3. Model 1 (In-House TDR)'!$G$10*12))*(1+'3. Model 1 (In-House TDR)'!$G$14)^INT((3-1)/2))*$Q30)*(1-'3. Model 1 (In-House TDR)'!$G$15))-'3. Model 1 (In-House TDR)'!$D$26 | G30: =((((('3. Model 1 (In-House TDR)'!$G$7*$P30*12)+('3. Model 1 (In-House TDR)'!$G$10*12))*(1+'3. Model 1 (In-House TDR)'!$G$14)^INT((4-1)/2))*$Q30)*(1-'3. Model 1 (In-House TDR)'!$G$15))-'3. Model 1 (In-House TDR)'!$D$26 | H30: =((((('3. Model 1 (In-House TDR)'!$G$7*$P30*12)+('3. Model 1 (In-House TDR)'!$G$10*12))*(1+'3. Model 1 (In-House TDR)'!$G$14)^INT((5-1)/2))*$Q30)*(1-'3. Model 1 (In-House TDR)'!$G$15))-'3. Model 1 (In-House TDR)'!$D$26 | I30: =((((('3. Model 1 (In-House TDR)'!$G$7*$P30*12)+('3. Model 1 (In-House TDR)'!$G$10*12))*(1+'3. Model 1 (In-House TDR)'!$G$14)^INT((6-1)/2))*$Q30)*(1-'3. Model 1 (In-House TDR)'!$G$15))-'3. Model 1 (In-House TDR)'!$D$26 | J30: =((((('3. Model 1 (In-House TDR)'!$G$7*$P30*12)+('3. Model 1 (In-House TDR)'!$G$10*12))*(1+'3. Model 1 (In-House TDR)'!$G$14)^INT((7-1)/2))*$Q30)*(1-'3. Model 1 (In-House TDR)'!$G$15))-'3. Model 1 (In-House TDR)'!$D$26 | K30: =((((('3. Model 1 (In-House TDR)'!$G$7*$P30*12)+('3. Model 1 (In-House TDR)'!$G$10*12))*(1+'3. Model 1 (In-House TDR)'!$G$14)^INT((8-1)/2))*$Q30)*(1-'3. Model 1 (In-House TDR)'!$G$15))-'3. Model 1 (In-House TDR)'!$D$26 | L30: =((((('3. Model 1 (In-House TDR)'!$G$7*$P30*12)+('3. Model 1 (In-House TDR)'!$G$10*12))*(1+'3. Model 1 (In-House TDR)'!$G$14)^INT((9-1)/2))*$Q30)*(1-'3. Model 1 (In-House TDR)'!$G$15))-'3. Model 1 (In-House TDR)'!$D$26 | M30: =((((('3. Model 1 (In-House TDR)'!$G$7*$P30*12)+('3. Model 1 (In-House TDR)'!$G$10*12))*(1+'3. Model 1 (In-House TDR)'!$G$14)^INT((10-1)/2))*$Q30)*(1-'3. Model 1 (In-House TDR)'!$G$15))-'3. Model 1 (In-House TDR)'!$D$26 | N30: =IRR(C30:M30) | P30: 18000 | Q30: 0.9
B31: ="Rent ₹"&TEXT(P31,"#,##0")&" @ "&TEXT(Q31,"0%")&" occ." | C31: =-'3. Model 1 (In-House TDR)'!$C$13 | D31: =((((('3. Model 1 (In-House TDR)'!$G$7*$P31*12)+('3. Model 1 (In-House TDR)'!$G$10*12))*(1+'3. Model 1 (In-House TDR)'!$G$14)^INT((1-1)/2))*'3. Model 1 (In-House TDR)'!$G$12)*(1-'3. Model 1 (In-House TDR)'!$G$15))-'3. Model 1 (In-House TDR)'!$D$26 | E31: =((((('3. Model 1 (In-House TDR)'!$G$7*$P31*12)+('3. Model 1 (In-House TDR)'!$G$10*12))*(1+'3. Model 1 (In-House TDR)'!$G$14)^INT((2-1)/2))*$Q31)*(1-'3. Model 1 (In-House TDR)'!$G$15))-'3. Model 1 (In-House TDR)'!$D$26 | F31: =((((('3. Model 1 (In-House TDR)'!$G$7*$P31*12)+('3. Model 1 (In-House TDR)'!$G$10*12))*(1+'3. Model 1 (In-House TDR)'!$G$14)^INT((3-1)/2))*$Q31)*(1-'3. Model 1 (In-House TDR)'!$G$15))-'3. Model 1 (In-House TDR)'!$D$26 | G31: =((((('3. Model 1 (In-House TDR)'!$G$7*$P31*12)+('3. Model 1 (In-House TDR)'!$G$10*12))*(1+'3. Model 1 (In-House TDR)'!$G$14)^INT((4-1)/2))*$Q31)*(1-'3. Model 1 (In-House TDR)'!$G$15))-'3. Model 1 (In-House TDR)'!$D$26 | H31: =((((('3. Model 1 (In-House TDR)'!$G$7*$P31*12)+('3. Model 1 (In-House TDR)'!$G$10*12))*(1+'3. Model 1 (In-House TDR)'!$G$14)^INT((5-1)/2))*$Q31)*(1-'3. Model 1 (In-House TDR)'!$G$15))-'3. Model 1 (In-House TDR)'!$D$26 | I31: =((((('3. Model 1 (In-House TDR)'!$G$7*$P31*12)+('3. Model 1 (In-House TDR)'!$G$10*12))*(1+'3. Model 1 (In-House TDR)'!$G$14)^INT((6-1)/2))*$Q31)*(1-'3. Model 1 (In-House TDR)'!$G$15))-'3. Model 1 (In-House TDR)'!$D$26 | J31: =((((('3. Model 1 (In-House TDR)'!$G$7*$P31*12)+('3. Model 1 (In-House TDR)'!$G$10*12))*(1+'3. Model 1 (In-House TDR)'!$G$14)^INT((7-1)/2))*$Q31)*(1-'3. Model 1 (In-House TDR)'!$G$15))-'3. Model 1 (In-House TDR)'!$D$26 | K31: =((((('3. Model 1 (In-House TDR)'!$G$7*$P31*12)+('3. Model 1 (In-House TDR)'!$G$10*12))*(1+'3. Model 1 (In-House TDR)'!$G$14)^INT((8-1)/2))*$Q31)*(1-'3. Model 1 (In-House TDR)'!$G$15))-'3. Model 1 (In-House TDR)'!$D$26 | L31: =((((('3. Model 1 (In-House TDR)'!$G$7*$P31*12)+('3. Model 1 (In-House TDR)'!$G$10*12))*(1+'3. Model 1 (In-House TDR)'!$G$14)^INT((9-1)/2))*$Q31)*(1-'3. Model 1 (In-House TDR)'!$G$15))-'3. Model 1 (In-House TDR)'!$D$26 | M31: =((((('3. Model 1 (In-House TDR)'!$G$7*$P31*12)+('3. Model 1 (In-House TDR)'!$G$10*12))*(1+'3. Model 1 (In-House TDR)'!$G$14)^INT((10-1)/2))*$Q31)*(1-'3. Model 1 (In-House TDR)'!$G$15))-'3. Model 1 (In-House TDR)'!$D$26 | N31: =IRR(C31:M31) | P31: 18000 | Q31: 0.92
B32: ="Rent ₹"&TEXT(P32,"#,##0")&" @ "&TEXT(Q32,"0%")&" occ." | C32: =-'3. Model 1 (In-House TDR)'!$C$13 | D32: =((((('3. Model 1 (In-House TDR)'!$G$7*$P32*12)+('3. Model 1 (In-House TDR)'!$G$10*12))*(1+'3. Model 1 (In-House TDR)'!$G$14)^INT((1-1)/2))*'3. Model 1 (In-House TDR)'!$G$12)*(1-'3. Model 1 (In-House TDR)'!$G$15))-'3. Model 1 (In-House TDR)'!$D$26 | E32: =((((('3. Model 1 (In-House TDR)'!$G$7*$P32*12)+('3. Model 1 (In-House TDR)'!$G$10*12))*(1+'3. Model 1 (In-House TDR)'!$G$14)^INT((2-1)/2))*$Q32)*(1-'3. Model 1 (In-House TDR)'!$G$15))-'3. Model 1 (In-House TDR)'!$D$26 | F32: =((((('3. Model 1 (In-House TDR)'!$G$7*$P32*12)+('3. Model 1 (In-House TDR)'!$G$10*12))*(1+'3. Model 1 (In-House TDR)'!$G$14)^INT((3-1)/2))*$Q32)*(1-'3. Model 1 (In-House TDR)'!$G$15))-'3. Model 1 (In-House TDR)'!$D$26 | G32: =((((('3. Model 1 (In-House TDR)'!$G$7*$P32*12)+('3. Model 1 (In-House TDR)'!$G$10*12))*(1+'3. Model 1 (In-House TDR)'!$G$14)^INT((4-1)/2))*$Q32)*(1-'3. Model 1 (In-House TDR)'!$G$15))-'3. Model 1 (In-House TDR)'!$D$26 | H32: =((((('3. Model 1 (In-House TDR)'!$G$7*$P32*12)+('3. Model 1 (In-House TDR)'!$G$10*12))*(1+'3. Model 1 (In-House TDR)'!$G$14)^INT((5-1)/2))*$Q32)*(1-'3. Model 1 (In-House TDR)'!$G$15))-'3. Model 1 (In-House TDR)'!$D$26 | I32: =((((('3. Model 1 (In-House TDR)'!$G$7*$P32*12)+('3. Model 1 (In-House TDR)'!$G$10*12))*(1+'3. Model 1 (In-House TDR)'!$G$14)^INT((6-1)/2))*$Q32)*(1-'3. Model 1 (In-House TDR)'!$G$15))-'3. Model 1 (In-House TDR)'!$D$26 | J32: =((((('3. Model 1 (In-House TDR)'!$G$7*$P32*12)+('3. Model 1 (In-House TDR)'!$G$10*12))*(1+'3. Model 1 (In-House TDR)'!$G$14)^INT((7-1)/2))*$Q32)*(1-'3. Model 1 (In-House TDR)'!$G$15))-'3. Model 1 (In-House TDR)'!$D$26 | K32: =((((('3. Model 1 (In-House TDR)'!$G$7*$P32*12)+('3. Model 1 (In-House TDR)'!$G$10*12))*(1+'3. Model 1 (In-House TDR)'!$G$14)^INT((8-1)/2))*$Q32)*(1-'3. Model 1 (In-House TDR)'!$G$15))-'3. Model 1 (In-House TDR)'!$D$26 | L32: =((((('3. Model 1 (In-House TDR)'!$G$7*$P32*12)+('3. Model 1 (In-House TDR)'!$G$10*12))*(1+'3. Model 1 (In-House TDR)'!$G$14)^INT((9-1)/2))*$Q32)*(1-'3. Model 1 (In-House TDR)'!$G$15))-'3. Model 1 (In-House TDR)'!$D$26 | M32: =((((('3. Model 1 (In-House TDR)'!$G$7*$P32*12)+('3. Model 1 (In-House TDR)'!$G$10*12))*(1+'3. Model 1 (In-House TDR)'!$G$14)^INT((10-1)/2))*$Q32)*(1-'3. Model 1 (In-House TDR)'!$G$15))-'3. Model 1 (In-House TDR)'!$D$26 | N32: =IRR(C32:M32) | P32: 18000 | Q32: 0.95
B33: ="Rent ₹"&TEXT(P33,"#,##0")&" @ "&TEXT(Q33,"0%")&" occ." | C33: =-'3. Model 1 (In-House TDR)'!$C$13 | D33: =((((('3. Model 1 (In-House TDR)'!$G$7*$P33*12)+('3. Model 1 (In-House TDR)'!$G$10*12))*(1+'3. Model 1 (In-House TDR)'!$G$14)^INT((1-1)/2))*'3. Model 1 (In-House TDR)'!$G$12)*(1-'3. Model 1 (In-House TDR)'!$G$15))-'3. Model 1 (In-House TDR)'!$D$26 | E33: =((((('3. Model 1 (In-House TDR)'!$G$7*$P33*12)+('3. Model 1 (In-House TDR)'!$G$10*12))*(1+'3. Model 1 (In-House TDR)'!$G$14)^INT((2-1)/2))*$Q33)*(1-'3. Model 1 (In-House TDR)'!$G$15))-'3. Model 1 (In-House TDR)'!$D$26 | F33: =((((('3. Model 1 (In-House TDR)'!$G$7*$P33*12)+('3. Model 1 (In-House TDR)'!$G$10*12))*(1+'3. Model 1 (In-House TDR)'!$G$14)^INT((3-1)/2))*$Q33)*(1-'3. Model 1 (In-House TDR)'!$G$15))-'3. Model 1 (In-House TDR)'!$D$26 | G33: =((((('3. Model 1 (In-House TDR)'!$G$7*$P33*12)+('3. Model 1 (In-House TDR)'!$G$10*12))*(1+'3. Model 1 (In-House TDR)'!$G$14)^INT((4-1)/2))*$Q33)*(1-'3. Model 1 (In-House TDR)'!$G$15))-'3. Model 1 (In-House TDR)'!$D$26 | H33: =((((('3. Model 1 (In-House TDR)'!$G$7*$P33*12)+('3. Model 1 (In-House TDR)'!$G$10*12))*(1+'3. Model 1 (In-House TDR)'!$G$14)^INT((5-1)/2))*$Q33)*(1-'3. Model 1 (In-House TDR)'!$G$15))-'3. Model 1 (In-House TDR)'!$D$26 | I33: =((((('3. Model 1 (In-House TDR)'!$G$7*$P33*12)+('3. Model 1 (In-House TDR)'!$G$10*12))*(1+'3. Model 1 (In-House TDR)'!$G$14)^INT((6-1)/2))*$Q33)*(1-'3. Model 1 (In-House TDR)'!$G$15))-'3. Model 1 (In-House TDR)'!$D$26 | J33: =((((('3. Model 1 (In-House TDR)'!$G$7*$P33*12)+('3. Model 1 (In-House TDR)'!$G$10*12))*(1+'3. Model 1 (In-House TDR)'!$G$14)^INT((7-1)/2))*$Q33)*(1-'3. Model 1 (In-House TDR)'!$G$15))-'3. Model 1 (In-House TDR)'!$D$26 | K33: =((((('3. Model 1 (In-House TDR)'!$G$7*$P33*12)+('3. Model 1 (In-House TDR)'!$G$10*12))*(1+'3. Model 1 (In-House TDR)'!$G$14)^INT((8-1)/2))*$Q33)*(1-'3. Model 1 (In-House TDR)'!$G$15))-'3. Model 1 (In-House TDR)'!$D$26 | L33: =((((('3. Model 1 (In-House TDR)'!$G$7*$P33*12)+('3. Model 1 (In-House TDR)'!$G$10*12))*(1+'3. Model 1 (In-House TDR)'!$G$14)^INT((9-1)/2))*$Q33)*(1-'3. Model 1 (In-House TDR)'!$G$15))-'3. Model 1 (In-House TDR)'!$D$26 | M33: =((((('3. Model 1 (In-House TDR)'!$G$7*$P33*12)+('3. Model 1 (In-House TDR)'!$G$10*12))*(1+'3. Model 1 (In-House TDR)'!$G$14)^INT((10-1)/2))*$Q33)*(1-'3. Model 1 (In-House TDR)'!$G$15))-'3. Model 1 (In-House TDR)'!$D$26 | N33: =IRR(C33:M33) | P33: 20000 | Q33: 0.8
B34: ="Rent ₹"&TEXT(P34,"#,##0")&" @ "&TEXT(Q34,"0%")&" occ." | C34: =-'3. Model 1 (In-House TDR)'!$C$13 | D34: =((((('3. Model 1 (In-House TDR)'!$G$7*$P34*12)+('3. Model 1 (In-House TDR)'!$G$10*12))*(1+'3. Model 1 (In-House TDR)'!$G$14)^INT((1-1)/2))*'3. Model 1 (In-House TDR)'!$G$12)*(1-'3. Model 1 (In-House TDR)'!$G$15))-'3. Model 1 (In-House TDR)'!$D$26 | E34: =((((('3. Model 1 (In-House TDR)'!$G$7*$P34*12)+('3. Model 1 (In-House TDR)'!$G$10*12))*(1+'3. Model 1 (In-House TDR)'!$G$14)^INT((2-1)/2))*$Q34)*(1-'3. Model 1 (In-House TDR)'!$G$15))-'3. Model 1 (In-House TDR)'!$D$26 | F34: =((((('3. Model 1 (In-House TDR)'!$G$7*$P34*12)+('3. Model 1 (In-House TDR)'!$G$10*12))*(1+'3. Model 1 (In-House TDR)'!$G$14)^INT((3-1)/2))*$Q34)*(1-'3. Model 1 (In-House TDR)'!$G$15))-'3. Model 1 (In-House TDR)'!$D$26 | G34: =((((('3. Model 1 (In-House TDR)'!$G$7*$P34*12)+('3. Model 1 (In-House TDR)'!$G$10*12))*(1+'3. Model 1 (In-House TDR)'!$G$14)^INT((4-1)/2))*$Q34)*(1-'3. Model 1 (In-House TDR)'!$G$15))-'3. Model 1 (In-House TDR)'!$D$26 | H34: =((((('3. Model 1 (In-House TDR)'!$G$7*$P34*12)+('3. Model 1 (In-House TDR)'!$G$10*12))*(1+'3. Model 1 (In-House TDR)'!$G$14)^INT((5-1)/2))*$Q34)*(1-'3. Model 1 (In-House TDR)'!$G$15))-'3. Model 1 (In-House TDR)'!$D$26 | I34: =((((('3. Model 1 (In-House TDR)'!$G$7*$P34*12)+('3. Model 1 (In-House TDR)'!$G$10*12))*(1+'3. Model 1 (In-House TDR)'!$G$14)^INT((6-1)/2))*$Q34)*(1-'3. Model 1 (In-House TDR)'!$G$15))-'3. Model 1 (In-House TDR)'!$D$26 | J34: =((((('3. Model 1 (In-House TDR)'!$G$7*$P34*12)+('3. Model 1 (In-House TDR)'!$G$10*12))*(1+'3. Model 1 (In-House TDR)'!$G$14)^INT((7-1)/2))*$Q34)*(1-'3. Model 1 (In-House TDR)'!$G$15))-'3. Model 1 (In-House TDR)'!$D$26 | K34: =((((('3. Model 1 (In-House TDR)'!$G$7*$P34*12)+('3. Model 1 (In-House TDR)'!$G$10*12))*(1+'3. Model 1 (In-House TDR)'!$G$14)^INT((8-1)/2))*$Q34)*(1-'3. Model 1 (In-House TDR)'!$G$15))-'3. Model 1 (In-House TDR)'!$D$26 | L34: =((((('3. Model 1 (In-House TDR)'!$G$7*$P34*12)+('3. Model 1 (In-House TDR)'!$G$10*12))*(1+'3. Model 1 (In-House TDR)'!$G$14)^INT((9-1)/2))*$Q34)*(1-'3. Model 1 (In-House TDR)'!$G$15))-'3. Model 1 (In-House TDR)'!$D$26 | M34: =((((('3. Model 1 (In-House TDR)'!$G$7*$P34*12)+('3. Model 1 (In-House TDR)'!$G$10*12))*(1+'3. Model 1 (In-House TDR)'!$G$14)^INT((10-1)/2))*$Q34)*(1-'3. Model 1 (In-House TDR)'!$G$15))-'3. Model 1 (In-House TDR)'!$D$26 | N34: =IRR(C34:M34) | P34: 20000 | Q34: 0.85
B35: ="Rent ₹"&TEXT(P35,"#,##0")&" @ "&TEXT(Q35,"0%")&" occ." | C35: =-'3. Model 1 (In-House TDR)'!$C$13 | D35: =((((('3. Model 1 (In-House TDR)'!$G$7*$P35*12)+('3. Model 1 (In-House TDR)'!$G$10*12))*(1+'3. Model 1 (In-House TDR)'!$G$14)^INT((1-1)/2))*'3. Model 1 (In-House TDR)'!$G$12)*(1-'3. Model 1 (In-House TDR)'!$G$15))-'3. Model 1 (In-House TDR)'!$D$26 | E35: =((((('3. Model 1 (In-House TDR)'!$G$7*$P35*12)+('3. Model 1 (In-House TDR)'!$G$10*12))*(1+'3. Model 1 (In-House TDR)'!$G$14)^INT((2-1)/2))*$Q35)*(1-'3. Model 1 (In-House TDR)'!$G$15))-'3. Model 1 (In-House TDR)'!$D$26 | F35: =((((('3. Model 1 (In-House TDR)'!$G$7*$P35*12)+('3. Model 1 (In-House TDR)'!$G$10*12))*(1+'3. Model 1 (In-House TDR)'!$G$14)^INT((3-1)/2))*$Q35)*(1-'3. Model 1 (In-House TDR)'!$G$15))-'3. Model 1 (In-House TDR)'!$D$26 | G35: =((((('3. Model 1 (In-House TDR)'!$G$7*$P35*12)+('3. Model 1 (In-House TDR)'!$G$10*12))*(1+'3. Model 1 (In-House TDR)'!$G$14)^INT((4-1)/2))*$Q35)*(1-'3. Model 1 (In-House TDR)'!$G$15))-'3. Model 1 (In-House TDR)'!$D$26 | H35: =((((('3. Model 1 (In-House TDR)'!$G$7*$P35*12)+('3. Model 1 (In-House TDR)'!$G$10*12))*(1+'3. Model 1 (In-House TDR)'!$G$14)^INT((5-1)/2))*$Q35)*(1-'3. Model 1 (In-House TDR)'!$G$15))-'3. Model 1 (In-House TDR)'!$D$26 | I35: =((((('3. Model 1 (In-House TDR)'!$G$7*$P35*12)+('3. Model 1 (In-House TDR)'!$G$10*12))*(1+'3. Model 1 (In-House TDR)'!$G$14)^INT((6-1)/2))*$Q35)*(1-'3. Model 1 (In-House TDR)'!$G$15))-'3. Model 1 (In-House TDR)'!$D$26 | J35: =((((('3. Model 1 (In-House TDR)'!$G$7*$P35*12)+('3. Model 1 (In-House TDR)'!$G$10*12))*(1+'3. Model 1 (In-House TDR)'!$G$14)^INT((7-1)/2))*$Q35)*(1-'3. Model 1 (In-House TDR)'!$G$15))-'3. Model 1 (In-House TDR)'!$D$26 | K35: =((((('3. Model 1 (In-House TDR)'!$G$7*$P35*12)+('3. Model 1 (In-House TDR)'!$G$10*12))*(1+'3. Model 1 (In-House TDR)'!$G$14)^INT((8-1)/2))*$Q35)*(1-'3. Model 1 (In-House TDR)'!$G$15))-'3. Model 1 (In-House TDR)'!$D$26 | L35: =((((('3. Model 1 (In-House TDR)'!$G$7*$P35*12)+('3. Model 1 (In-House TDR)'!$G$10*12))*(1+'3. Model 1 (In-House TDR)'!$G$14)^INT((9-1)/2))*$Q35)*(1-'3. Model 1 (In-House TDR)'!$G$15))-'3. Model 1 (In-House TDR)'!$D$26 | M35: =((((('3. Model 1 (In-House TDR)'!$G$7*$P35*12)+('3. Model 1 (In-House TDR)'!$G$10*12))*(1+'3. Model 1 (In-House TDR)'!$G$14)^INT((10-1)/2))*$Q35)*(1-'3. Model 1 (In-House TDR)'!$G$15))-'3. Model 1 (In-House TDR)'!$D$26 | N35: =IRR(C35:M35) | P35: 20000 | Q35: 0.9
B36: ="Rent ₹"&TEXT(P36,"#,##0")&" @ "&TEXT(Q36,"0%")&" occ." | C36: =-'3. Model 1 (In-House TDR)'!$C$13 | D36: =((((('3. Model 1 (In-House TDR)'!$G$7*$P36*12)+('3. Model 1 (In-House TDR)'!$G$10*12))*(1+'3. Model 1 (In-House TDR)'!$G$14)^INT((1-1)/2))*'3. Model 1 (In-House TDR)'!$G$12)*(1-'3. Model 1 (In-House TDR)'!$G$15))-'3. Model 1 (In-House TDR)'!$D$26 | E36: =((((('3. Model 1 (In-House TDR)'!$G$7*$P36*12)+('3. Model 1 (In-House TDR)'!$G$10*12))*(1+'3. Model 1 (In-House TDR)'!$G$14)^INT((2-1)/2))*$Q36)*(1-'3. Model 1 (In-House TDR)'!$G$15))-'3. Model 1 (In-House TDR)'!$D$26 | F36: =((((('3. Model 1 (In-House TDR)'!$G$7*$P36*12)+('3. Model 1 (In-House TDR)'!$G$10*12))*(1+'3. Model 1 (In-House TDR)'!$G$14)^INT((3-1)/2))*$Q36)*(1-'3. Model 1 (In-House TDR)'!$G$15))-'3. Model 1 (In-House TDR)'!$D$26 | G36: =((((('3. Model 1 (In-House TDR)'!$G$7*$P36*12)+('3. Model 1 (In-House TDR)'!$G$10*12))*(1+'3. Model 1 (In-House TDR)'!$G$14)^INT((4-1)/2))*$Q36)*(1-'3. Model 1 (In-House TDR)'!$G$15))-'3. Model 1 (In-House TDR)'!$D$26 | H36: =((((('3. Model 1 (In-House TDR)'!$G$7*$P36*12)+('3. Model 1 (In-House TDR)'!$G$10*12))*(1+'3. Model 1 (In-House TDR)'!$G$14)^INT((5-1)/2))*$Q36)*(1-'3. Model 1 (In-House TDR)'!$G$15))-'3. Model 1 (In-House TDR)'!$D$26 | I36: =((((('3. Model 1 (In-House TDR)'!$G$7*$P36*12)+('3. Model 1 (In-House TDR)'!$G$10*12))*(1+'3. Model 1 (In-House TDR)'!$G$14)^INT((6-1)/2))*$Q36)*(1-'3. Model 1 (In-House TDR)'!$G$15))-'3. Model 1 (In-House TDR)'!$D$26 | J36: =((((('3. Model 1 (In-House TDR)'!$G$7*$P36*12)+('3. Model 1 (In-House TDR)'!$G$10*12))*(1+'3. Model 1 (In-House TDR)'!$G$14)^INT((7-1)/2))*$Q36)*(1-'3. Model 1 (In-House TDR)'!$G$15))-'3. Model 1 (In-House TDR)'!$D$26 | K36: =((((('3. Model 1 (In-House TDR)'!$G$7*$P36*12)+('3. Model 1 (In-House TDR)'!$G$10*12))*(1+'3. Model 1 (In-House TDR)'!$G$14)^INT((8-1)/2))*$Q36)*(1-'3. Model 1 (In-House TDR)'!$G$15))-'3. Model 1 (In-House TDR)'!$D$26 | L36: =((((('3. Model 1 (In-House TDR)'!$G$7*$P36*12)+('3. Model 1 (In-House TDR)'!$G$10*12))*(1+'3. Model 1 (In-House TDR)'!$G$14)^INT((9-1)/2))*$Q36)*(1-'3. Model 1 (In-House TDR)'!$G$15))-'3. Model 1 (In-House TDR)'!$D$26 | M36: =((((('3. Model 1 (In-House TDR)'!$G$7*$P36*12)+('3. Model 1 (In-House TDR)'!$G$10*12))*(1+'3. Model 1 (In-House TDR)'!$G$14)^INT((10-1)/2))*$Q36)*(1-'3. Model 1 (In-House TDR)'!$G$15))-'3. Model 1 (In-House TDR)'!$D$26 | N36: =IRR(C36:M36) | P36: 20000 | Q36: 0.92
